Workbook
Name SlicerCache_Table_1_Col_1: #N/A

Sheet Introduction
A1: Context:
A2: The Global Open Research Commons International Model Working Group (GORC-WG) has been working to create a model describing commons* attributes* so that commons* developers can compare aspects across research clouds and commons*.
A4: This is the GORC WG commons* model version* 1.1. It represents the work done by the GORC-WG culminating in V1.0 of the model endorsed by RDA in October 2023, with slight revisions. Note that additional versions* of this model, as well as implementations and applications of it, are under development, and will be released in the future.
A6: What the model is:
A7: This spreadsheet representation of the model includes a flat breakdown of the essential elements* of a commons* (from the GORC-IG definitions document, see below), categories* and subcategories* of these essential elements*, and the attributes* and features* that exist for each. Of note is the relationship between all aspects of the model as presented here: the entities of essential elements*, categories*, and subcategories*, and the characteristics (attributes* and features*) that belong to them. Subcategories* are child entities of categories*, and categories* are child entities of essential elements*. Attributes* are inherited from parent to child entities, but are not necessarily shared between sibling entities. Features* are more granular than attributes*. Categories* of essential elements* may be considered mandatory and not disjoint, in the way that any entity that is part of the essential element* must belong to a category* of the essential element and may belong to more than one category*. Subcategories* are optional and not disjoint, in the way that any entity that is part of a category* may or may not belong to a subcategory*, and belong to more than one subcategory*. Possible Key Performance Idicators* (KPIs*) and metrics* for consideration are listed in the last tab. A UML visual representation of these relationships is available in this conceptual model. In addition to the statement of the model (i.e. the name of each essential element*, category*, subcategory*, attribute*, feature*, and KPI*), there are extended descriptions, examples, consideration levels*, and a listing of the source or sources where the item originated. The model is not intended to be prescriptive or indicate how any one commons* should be structured or operate, and so the consideration level* provides a gentle guide on the priority for which aspects of the model should be considered. This does not indicate that items with "Core" consideration levels* must be implemented, but that the GORC-WG has identified them as important and therefore they should be considered by any and all commons* at any development stage*. Similarly, "Desirable" items may be less critical for all commons* to consider and may be more suited to established commons*, and "Optional" for mature commons* or commons* with specific interest in those areas of work.
A9: Any word throughout the model with an asterisk (*) has a specific definition captured in the glossary. In some cases, the same word may have different meanings depending on context, and so the same word may have an asterisk in one place and no asterisk when used in another part of the model as it means something different than our model-specific definition, especially within examples. Each essential element* in the model has its own tab. Blue coloured cells indicate categories* and their information, and purple cells indicate subcategories* and their information. Orange coloured cells indicate attributes* and their information, and yellow cells indicate features* and their information. Attributes* and features* at the top of each tab that are not within a category* or subcategory* belong to the essential element*, and are inherited by each category* and subcategory*. Attributes* and features* that belong to categories* are inherited by that category's* subcategories*. Subcategories* may also have attributes* and features*, which are not necessarily shared with sibling subcategories*. The ordering of categories*, subcategories*, attributes*, and features* within each tab is not indicative of importance.
A11: How to use the model | C11: Counts
A12: Commons* developers may use this model as a guide for what to consider as they build, maintain, and expand their commons*. Not every commons* should include every item in this model, however we encourage commons* to consider having some representation in each essential element*. Commons* developers should review and consider each attribute* and feature* and the subcategories* and categories* they belong to in each essential element*, asking themselves if each is something their commons* has at a sufficient level, has but needs to improve or expand, does not have and needs immediately, does not have and needs eventually, or doesn't need at all. Developers may consider keeping explanatory notes for themselves on their decisions for each item in the model, and revisiting them over time as part of their strategic planning process. Developers may find the list of possible KPIs and metrics helpful as a starting point to determine their own success indicators and metrics. A first edition adoption tool , based on V1.0, is available for those interested in adopting the model. Note that the access level on this sheet is set to "anyone can comment". Please do leave comments and suggestions on cells throughout the model. All parts of the model should be visible, but please contact CJ at c.joseph.woodford@gmail.com if you find you cannot see any area of the model clearly. We also have a running list of issues/considerations for future versions that address overarching ideas and potential changes. To assist with determining which components of the model to consider first, each tab has a slicer in cell 1E that allows you to select whether you view all items at once or only items of a particular consideration level* at a time. A counter at the top of each sheet will inform you of how many items you are currently viewing. The totals for each essential element are to the right for reference. | C12: Essential Element* | D12: Total items | E12: Core Considerations | F12: Desirable Considerations | G12: Optional Considerations | H12: Categories* | I12: Subcategories* | J12: Attributes* & Features
C13: Governance & Leadership* | D13: =SUM(H13:I13,J13) -> 59 | E13: =COUNTIF('Governance & Leadership'!G:G, "Core") -> 41 | F13: =COUNTIF('Governance & Leadership'!G:G, "Desirable") -> 18 | G13: =COUNTIF('Governance & Leadership'!G:G, "Optional") -> 0 | H13: 5 | I13: 6 | J13: 48
A14: Relevant Resources: | C14: Rules of Participation & Access* | D14: =SUM(H14:I14,J14) -> 15 | E14: =COUNTIF('Rules of Participation & Access'!G:G, "Core") -> 11 | F14: =COUNTIF('Rules of Participation & Access'!G:G, "Desirable") -> 4 | G14: =COUNTIF('Rules of Participation & Access'!G:G, "Optional") -> 0 | H14: 2 | I14: 8 | J14: 5
A15: Global Open Research Commons International Model, version 1.1, Model documentation | C15: Sustainability* | D15: =SUM(H15:I15,J15) -> 12 | E15: =COUNTIF(Sustainability!G:G, "Core") -> 5 | F15: =COUNTIF(Sustainability!G:G, "Desirable") -> 5 | G15: =COUNTIF(Sustainability!G:G, "Optional") -> 2 | H15: 3 | I15: 5 | J15: 4
A16: The Global Open Research Commons International Model, version 1, supporting documentation; https://zenodo.org/records/10032913 | C16: Engagement* | D16: =SUM(H16:I16,J16) -> 17 | E16: =COUNTIF(Engagement!G:G, "Core") -> 11 | F16: =COUNTIF(Engagement!G:G, "Desirable") -> 5 | G16: =COUNTIF(Engagement!G:G, "Optional") -> 1 | H16: 4 | I16: 3 | J16: 10
A17: GORC IG: Typology and Definitions : https://doi.org/10.15497/RDA00087 | C17: Human Capacity* | D17: =SUM(H17:I17,J17) -> 27 | E17: =COUNTIF('Human Capacity'!G:G, "Core") -> 22 | F17: =COUNTIF('Human Capacity'!G:G, "Desirable") -> 5 | G17: =COUNTIF('Human Capacity'!G:G, "Optional") -> 0 | H17: 5 | I17: 1 | J17: 21
A18: GORC International Model WG - Commons Model V1.0 | C18: ICT Infrastructure* | D18: =SUM(H18:I18,J18) -> 28 | E18: =COUNTIF('ICT Infrastructure'!G:G, "Core") -> 20 | F18: =COUNTIF('ICT Infrastructure'!G:G, "Desirable") -> 4 | G18: =COUNTIF('ICT Infrastructure'!G:G, "Optional") -> 4 | H18: 5 | I18: 8 | J18: 15
C19: Interoperability* | D19: =SUM(H19:I19,J19) -> 21 | E19: =COUNTIF(Interoperability!G:G, "Core") -> 9 | F19: =COUNTIF(Interoperability!G:G, "Desirable") -> 11 | G19: =COUNTIF(Interoperability!G:G, "Optional") -> 1 | H19: 3 | I19: 3 | J19: 15
C20: Standards* & Conventions* | D20: =SUM(H20:I20,J20) -> 33 | E20: =COUNTIF('Standards & Conventions'!G:G, "Core") -> 10 | F20: =COUNTIF('Standards & Conventions'!G:G, "Desirable") -> 22 | G20: =COUNTIF('Standards & Conventions'!G:G, "Optional") -> 1 | H20: 10 | I20: 2 | J20: 21
C21: Services* & Tools* | D21: =SUM(H21:I21,J21) -> 74 | E21: =COUNTIF('Services & Tools'!G:G, "Core") -> 28 | F21: =COUNTIF('Services & Tools'!G:G, "Desirable") -> 36 | G21: =COUNTIF('Services & Tools'!G:G, "Optional") -> 10 | H21: 10 | I21: 10 | J21: 54
C22: Research Objects* | D22: =SUM(H22:I22,J22) -> 6 | E22: =COUNTIF('Research Objects'!G:G, "Core") -> 6 | F22: =COUNTIF('Research Objects'!G:G, "Desirable") -> 0 | G22: =COUNTIF('Research Objects'!G:G, "Optional") -> 0 | H22: 5 | I22: 0 | J22: 1
A23: © 2024. This work is licensed under a CC BY 4.0 license. Attribute as "Commons Model V1.1, GORC IM WG, 2024" | C23: Subtotals | D23: =SUM(D13:D22) -> 292 | E23: =SUM(E13:E22) -> 163 | F23: =SUM(F13:F22) -> 110 | G23: =SUM(G13:G22) -> 19 | H23: =SUM(H13:H22) -> 52 | I23: =SUM(I13:I22) -> 46 | J23: =SUM(J13:J22) -> 194
A24: Cite as: | C24: KPIs* & metrics* | D24: 104 | E24: =COUNTIF('KPIs & Metrics'!E:E, "Core") -> 49 | F24: =COUNTIF('KPIs & Metrics'!E:E, "Desirable") -> 34 | G24: =COUNTIF('KPIs & Metrics'!E:E, "Optional") -> 21
A25: Woodford, C. J., Treloar, A., Leggott, M., Payne, K.., Jones, S., Lopez Albacete, J., Madalli, D., Genova, F., Dharmawardena, K., Chibhira, N., Åkerström, W. N., Macneil, R., Nurnberger, A., Pfeiffenberger, H., Tanifuji, M., Zhang, Q., Jones, N., Sesink, L., & Wood-Charlson, E. (2024). The Global Open Research Commons International Model, Version 1.1 (Version 1.1). Research Data Alliance. https://doi.org/10.15497/RDA00119 | C25: Total Considerations: | D25: =D23+D24 -> 396 | E25: =SUM(E23:E24) -> 212 | F25: =SUM(F23:F24) -> 144 | G25: =SUM(G23:G24) -> 40
A27: Acknowlegements and thanks are extended to all GORC-WG members, speakers, and RDA community members who provided input to and feedback on the model. In particular, we thank Corrie, B., Crawley, F., Harrower, N., Maxwell, L., Sansone, S. A. for their contributions.

Sheet Glossary
A1: Glossary | B1: As much as possible, it is preferred we make definitions more inclusive rather than exclusive. This glossary is listed alphabetically. | C1: -
A2: Term | B2: Current definition | C2: Notes / source
A3: Attribute* | B3: A standard, characteristic, functionality or point of reference from which information can be documented, or measurements or comparisons may be made. Attributes* are the top level characteristics of entities (essential elements*, categories*, subcategories*). e.g. "Metadata content" is an attribute of the category "Metadata standards" within the "Standards & Conventions" essential element*. | C3: Adapted from the GORC-WG case statement
A4: Block-based Storage* | B4: Block storage is an approach to data storage in which each storage volume acts as an individual hard drive that is configured by the storage administrator. In the block storage model, data is saved to the storage media in fixed-sized chunks called blocks. Each block is associated with a unique address, and the address is the only Metadata* assigned to each block. | C4: Adapted from https://www.techtarget.com/searchstorage/definition/block-storage,
A5: Category*, Subcategory* | B5: A grouping or classification within an essential element* of items that share attributes* and features*. Categories* may be broken down further into subcategories*. Any attributes* and features* of the essential element* to which the category* belongs are inherited by that category*, and likewise by any subcategories*. For example, in the essential element* ICT Infrastructure*, the category* "Storage Infrastructure" has two subcategories*: "Direct attached storage [...]" and "Network based storage [...]". This category* has one attribute, "Knowledge and management of storage infrastructure", that is inherited by both of its subcategories*. Likewise, ICT Infrastructure* itself has two attributes, "Infrastructure is designed to scale with changing volume, complexity, and velocity of projects and expectations" and "A review and update of ICT infrastructure* happens on a regular basis". Both of these attributes, as well as the features in the latter, are inherited by the "Storage Infrastructure" category and its subcategories, such that any direct-attached, network-based, or other storage infrastructure a commons* has should have considerations for changing needs, be reviewed and updated, and have method(s) for accumulating and maintaining knowledge about them, such as a wiki. | C5: Task Group 5 Phase 2 Evaluation (May - September 2023), https://joeyhoer.com/attributes-vs-categories-6f3c9bab
A6: Collection* (of Research Objects*) | B6: A combination or bundle of Research Objects* that are of the same kind or different kinds that share a relationship, is treated as a digital object* which may bear a PID*, and consists of a finite number of digital object* identifiers and Metadata* associated with each referenced identifier. | C6: Research Data collections WG Recommendations, CURE-FAIR WG (10 things for curating reproducible and FAIR research), Speaker series (NII), Task Group 3 Phase 1 Evaluation (October 2022 - April 2023)
A7: Commons*, Research commons* | B7: A trusted ecosystem that provides seamless access to high quality, interoperable research outputs and Services*. While commons* may be focused on a specific discipline or geographic region, they should have the intent to be part of the global data ecosystem. The scope of this and related documents is intentionally restricted to digital information, and intentionally does not include the instruments that generate the data that may be made available through the commons*. | C7: Adapted from the GORC-IG typology
A8: Community*, Research commons community* or commons community* | B8: All human individuals and entities that could be considered stakeholders*, Users*, Providers*, Members* and intermediaries of the commons* (i.e. those who do not interact directly with the commons, but use information about or provided by the commons, e.g. policy makers, journals, funders) in the past, present, and future as well as all research communities that the research commons* is a part of in a regional, national, and global context. Depending on the structure of the commons*, may include funding and government bodies as well as related commercial entities, such as through related Services* or associated with related research communities. | C8: GORC-WG Phase 1 Evaluation (October 2022 - April 2023)
A9: Consideration Level* | B9: Consideration levels* indicate the priority or importance with which each item in the model should be considered. There are three levels, with 'Core' indicating items that are critical to consider for a commons* at any development stage* and in any discipline, 'Desirable' indicating items that should be considered by established commons* or those looking to expand, and 'Optional' indicating items that may be considered by commons* with particular interest in those areas. | C9: GORC-WG Phase 2 Evaluation (May - September 2023)
A10: Data space* | B10: Any digital location that incentivises the sharing of data and/or facilitates the use of data across any research discipline or field. Includes research data commons*, data Repositories*, data portals, research commons*, and any interlinked Service* such as HPC infrastructures or VRE platforms*. Note that data space*s may also be physical locations, but we are not concerned with physical data space*s in this model. | C10: Adapted from EOSC Monitoring Framework
A11: Development Stage* | B11: The stage that a commons* is in regarding its development. This speaks to the main goal of the commons* at present, spanning: Initial [getting building blocks in place, before development or implementation of external-facing services*], Developing [main foundation of commons* is in place and the commons* is starting to develop, trial, and open external facing services* and tools*], Established [recognized in research community with core services in place], Expanding [core services are well in place, looking to bolster current services and/or expand offerings/audience]. Note that "Established" may be the end goal for a commons*, as "Expanding" is specifically for growing beyond the original mission of the commons*. Additionally, development stage* is not the same as commons* age or maturity, since the time spent in any one stage will be context dependent, however development stage* and age may be correlated. Used in KPIs* & Metrics* as a guideline on when during their development a commons* may wish to consider particular measurements and indicators. | C11: Phase 2 Review (Literature Analysis, November 2022 - June 2023), adpated from Research Data Management Support Services by Libraries - A LIBER/ADBU Toolkit (https://zenodo.org/record/8101818)
A12: Digital object* | B12: A digital object* (DO*) is represented by a bitstream, is referenced and identified by a persistent identifier and has properties that are described by Metadata*. | C12: Adapted from RDA data foundation and terminology - DFT: Results RFC
... A22: Interoperability* (essential element*) | B22: The ability of Research Objects* or Tools* from different resources to integrate or work together with minimal effort. e.g. A research data file can be used by two different commons* HPC infrastructure. | C22: Adapted from the GORC-IG typology, from Wilkinson et al. 2016, essential element*
B23: Legal Interoperability*: A category* of Interoperability*. The ability to combine Research Objects* from multiple sources without conflicts among restrictions imposed by the license of each Research Object*; Research Objects* should be reusable. Covers the broad environment of laws, policies, procedures, and cooperations agreements needed to allow the seamless exchange of information and reusability of Research Objects* between difference individuals, organizations, and across jurisdictions. | C23: (EOSC FAIR-WG) EOSC Interoperability* framework - Publications Office of the EU [2021, https://data.europa.eu/doi/10.2777/620649]
B24: Organizational Interoperability*, Pragmatic Interoperability*: A category* of Interoperability*. How organizations align their business processes, responsibilities and expectations to achieve commonly agreed and mutually beneficial goals; meeting the requirements of the shared commons community* by making Services* available, easily identifiable, accessible, and community* member-focused Considerations for Interoperability* with other commons*, repos, public research institutions, private research institutions, and commercial entities, among other entities in the community*, are included. | C24: Adapted from (EOSC FAIR-WG) EOSC Interoperability* framework - Publications Office of the EU [2021, https://data.europa.eu/doi/10.2777/620649]
B25: Semantic Interoperability*: the ability of computer systems to transmit information with unambiguous, shared meaning; a requirement to enable machine computable logic, inference, knowledge discovery, and Research Object* federation between information systems; what is sent is what is understood by both humans and machines. | C25: (EOSC FAIR-WG) EOSC Interoperability* framework - Publications Office of the EU [2021, https://data.europa.eu/doi/10.2777/620649]
B26: Technical Interoperability*: the ability of different information technology systems and software applications to communicate and exchange Research Objects*, and specifically to accept Research Objects* from each other and perform a given task in an appropriate and satisfactory manner without the need for extra operator intervention. | C26: (EOSC FAIR-WG) EOSC Interoperability* framework - Publications Office of the EU [2021, https://data.europa.eu/doi/10.2777/620649]
A27: KPI*, Key Performance Indicator | B27: Qualitative and quantitative measures used within and by the commons* to measure the uptake, engagement or use of a category*, subcategory*, Attribute* or feature*. KPIs* are often used to measure success, adoption, and use specifically. | C27: Adapted from the GORC-WG case statement
A28: Machine Actionable* | B28: Machine Actionable* means that a formal statement is syntactically and semantically specified enabling computing systems to carry out automatic processing. | C28: (EOSC FAIR-WG) A Persistent Identifier (PID*) policy for the European Open Science Cloud (EOSC) - Publications Office of the EU [2020, https://data.europa.eu/doi/10.2777/926037]
A29: Members* | B29: A human individual or entity, such as research institutions, that participate in the commons*. Participation may include but is not limited to being Providers*, granting access or creating pathways for Users* to engage with the commons*, and participating in the governance* structure of the commons*. Being a member of a commons* is the highest level of interaction without being an employee or hosting organization. Eg. a member is participating on the Data Management Plan task group of the commons*. | C29: GORC-WG Phase 1 Evaluation (October 2022 - April 2023)
A30: Metadata* | B30: Information about the Research Object*, Service*, Tool*, or other entity being described. Often stated as "data about data". Metadata* typically contains descriptive, contextual and Provenance* assertions about the properties of a digital object*. | C30: GORC-WG Phase 1 Evaluation (October 2022 - April 2023)
A31: Metric* | B31: A metric* is a quantifiable measure that is used to track and assess the evolution or performance of specific processes | C31: A Set of Common Service Quality Assurance Baseline Criteria for Research Projects [2022] https://digital.csic.es/handle/10261/214441
A32: Object based Storage* | B32: A stored object is a logical collection* of bytes that are of variable size and can be used to store entire data structures, such as files, database tables, medical images, or multimedia. Object-based storage offers the efficiency of block storage and the control of file storage. | C32: Adapted from https://ieeexplore.ieee.org/document/1222722#citations
A33: PID*, Persistent Identifier* | B33: A persistent identifier* is a long-lasting ID represented by a string that uniquely identifies a digital object* and that is intended to be persistently resolved to meaningful state information about the identified digital object. A PID may also be defined by it's characteristics, i.e. that PIDs: are uniquely identifying a specific Digital Object*; in general consist of a name space indicator (prefix) and a local identifier (suffix); are actionable on the web, by extending it to a fully defined URI, if required; can be persistently resolved to state information and/or a landing page; are associated with a persistent resolution system; are issued and managed by a clearly specified registration authority. | C33: Adapted from Persistent Identifiers: Consolidated Assertions, from the RDA Data Fabric IG and RDA Data foundation and Terminology WG
A34: PID* record* | B34: A PID* record* or kernel is a minimal set of information about the digital object* communicated between machines. At minimum, it contains the pair between the PID* and the landing page or access URL for the Metadata*. | C34: Adapted from Persistent Identifiers: Consolidated Assertions, from the RDA Data Fabric IG and RDA Data foundation and Terminology WG D2.4 2nd report on FAIR requirements for persistence and Interoperability [2020, FAIRsFAIR]
A35: Platform*, Research Platform* | B35: Research platforms and Services* (virtual science labs, VREs, science gateways) instantiate a collection* of Research Software* source code, including large software frameworks, discipline-specific Tools*, Services*, and glue code, and are deployed to support both the research workflows and the communities of practise engaged in collaborative research. Capabilities include: DAM, processing and visualisation, storage and preservation, sharing and discovery. EX: FRDR, Syzygy, PIMS, CWRC | C35: Research Software* Current State Assessment [2021] (https://alliancecan.ca/sites/default/files/2022-03/rs_current_state_report_1.pdf)
A36: Provenance* | B36: Any and all information regarding the creation, curation, maintenance, context, rights and responsibility for a Research Object*. | C36: Influenced by https://ckaestne.medium.com/versioning*-Provenance*-and-reproducibility-in-production-machine-learning-355c48665005
A37: Providers* | B37: An individual or entity, human or machine, that provides Services*, Tools*, and/or Research Objects* to the commons* or to Users* on behalf of the commons*. Providers* may also be Users* and Members*. Ex. a Provider* deposits a dataset into the commons*' Repository*, a third-party company provides digitization Services* for commons* Users*
A38: Publishers* | B38: An entity, human or machine, that prepares and issues a Research Object* for distribution or otherwise makes the Research Object* public, so that it may be shared and discovered. This includes but is not limited to peer-review and open access journals, data Repositories*, government bodies, pre-print Repositories*, blogs, and digital spaces owned and operated by research institutions and organizations, such as websites and news columns. Specific examples include websites such as Zenodo, an institutional or discipline Repository* such as GBIF, or a software Repository* such as Github.
A39: Publication* | B39: A text based scholarly Publication* or publishing channel that contains results of research. CRISs typically record Metadata* about scholarly Publications* from the scope of the CRIS (institutional CRIS for the institution, funder CRIS for the funding it distributed, etc.) in the context of the research projects, infrastructure, funding, organization units and authors/contributors. This entity typically represents the granularity level of a single published item for which attribution information is attached (usually in the form of a list of authors and contributors). This entity is also used to represent publishing channels and sources: journals and book series (incl. continuing conference proceedings series). | C39: OpenAIRE Guidelines [2022] (https://guidelines.openaire.eu/en/latest/index.html) Publication* Metadata* in CERIF: Inspiration by FRBR (https://doi.org/10.1016/j.procs.2014.06.008)
A40: Repository*, Repositories*, Repo*, Repos* | B40: A system for Research Object* storage and management. Repositories* may aggregate Research Objects* from other Repositories*, and may be a part of or are harvested by commons*. Repositories* typically do not have Services* or Tools* beyond essential storage and management. | C40: Adapted from RDA data foundation and terminology - DFT: Results RFC
A41: Research Compendium* | B41: A bundle of all the research artifacts used and necessary to support a research claim, such that the claim is completely reproducible using only what is provided or referenced in the research compendium*. | C41: CURE-FAIR WG, 10 things for curating reproducible and FAIR research
A42: Research Data* | B42: An assembly of data that is identifiable and has the potential to be curated or published by a single actor and is the result or focus of research activities. Research data can digitally represent a group of observations, a data product from a specific version* of a processing algorithm based on observations, output of numerical model(s), or outcomes of laboratory experiments. Research data serve as the object(s) of an investigation, whether scientific, scholarly, literary or artistic, and are used to create more or other research data. | C42: Global Community Guidelines for Documenting, Sharing, and Reusing Quality Information of Individual Digital Datasets https://datascience.codata.org/articles/10.5334/dsj-2022-008/ Canadian Tri-Agency (https://science.gc.ca/eic/site/063.nsf/eng/h_97609.html#1a), Random Encounters (CANLIB discussion)
A43: Research Object* (essential element*), Research Artefact* | B43: Any input to, or output of, any and all stages of the research process. For this version of the model (V1.0), we only consider Research Objects* that are Digital Objects*, as we have confined the model to digital and e-infrastructures. | C43: Adapted from the GORC-IG typology, essential element*
A44: Research Software* | B44: Source code files, algorithms, scripts, computational workflows, and executables that were created during the research process or for a research purpose. Software components (e.g. operating systems, libraries, dependencies, packages, scripts, etc.) that are used for research but were not created during or with a clear research intent should be considered software in research and not Research Software*. | C44: Amsterdam Declaration on Funding Research Software* Sustainability [V0.3, 2023] (https://zenodo.org/record/7330542#.Y5ts83bMJdg)
A45: Rules of Participation & Access* (RoP) (essential element*) | B45: A set of policies defining a minimal set of rights, obligations, and accountability governing the activities of those participating in the commons*. | C45: Adapted from the GORC-IG typology, from EOSC, essential element*
A46: Semantic Artifacts, Semantic Objects* | B46: Semantic Objects* are a named grouping of descriptive elements that sufficiently describe a distinct identity. Semantic Objects* may be in the form of documentation, Research Software*, or research data*. They may also be referred to as Semantic Artefacts*, defined as groups of entities with unique identifiers where entities include subjects, predicates, and objects that can be linked together to form a network that describes a dataset. In this model, Semantic Objects*/Artefacts are not considered as collections, since collections are comprised of Research Objects* and not entities. | C46: Adapted from D2.1 Report on fair requirements for persistence and Interoperability [2019, FAIRsFAIR]
A47: Service* (essential element*) | B47: Any commons* element that can be invoked by Users* to perform some action on their behalf. | C47: Adapted from the GORC-IG typology, from IVOA, essential element*
B48: Data Service*: any Service* that acts on at least one component of the ‘holy trinity of data management’: the bit sequence, the Metadata* and the PID* of a digital object*. This includes Services* that bind these components together (e.g. associating Metadata* with a bit sequence), Services* that deliver data to the User*, Services* that automatically analyze or transform data, Services* that aggregate and index Metadata*, Services* that store or replicate data, etc | C48: M2.7: Assessment report on 'FAIRness of Services*' [2020, FAIRsFAIR] (https://doi.org/10.5281/zenodo.5470375)
A49: Stakeholder* | B49: Any human individual or entity that represent themself or a non-human (animal, plant, land, resource, or technology) entity or group that is associated with, is a member of, participates in, provides to, or uses the commons* past, present, and future. e.g. Producers, Users*, and re-Users* of research data; Funders of research infrastructures and the production of research data; Policy developers for research data management e.g. “Core”: governance* bodies and committees, Members*, secretariat; Funders and influencers: national ministries and agencies, public science funders and councils, intergovernmental bodies and organizations, foundations and charities, industry; Users*, data controbiters, data Publishers*: individuals and organizations such as intergovernmental bodies and others, and projects; Discipline or otherwise related informatics: other infrastructures, IT departments at related institutions, standardization bodies, projects, and other initiatives | C49: Briefing Paper on EOSC: Federating Research Infrastructures in Europe for Fair Access to Data [2022] (https://www.scienceeurope.org/our-resources/briefing-paper-on-eosc/) Twenty-Year Review of GBIF (https://doi.org/10.35035/ctzm-hz97)
...

Sheet Governance & Leadership
A1: Essential Element*: Governance & Leadership* | C1: Items in active view: | D1: =SUBTOTAL(103, G3:G61) -> 59 | E1: - | F1: - | G1: - | H1: -
A2: Category* | B2: Subcategory* | C2: Attribute* | D2: Feature* | E2: Extended Description | F2: Examples | G2: Consideration Level* | H2: Primary Source(s)
A3: Commons* intent and definition | E3: - | F3: - | G3: Core | H3: Phase 2 Review (Literature Analysis, November 2022 - June 2023)
C4: Statement of current commons* nature, mandate, and value proposition. Reference to any prior mandates and how the commons* has changed over time. | E4: - | F4: e.g. type of authority (formally government mandated or informally community* driven), scope of Services* e.g. the commons* carefully considers actions to avoid scope creep, i.e. unplanned or unmanaged growth, that could cause issues with resources or impede on other organizations’ area of work. | G4: Core | H4: Phase 1 Workshop (co-located with RDA P20, 24 March 2023) Twenty-Year Review of GBIF (https://doi.org/10.35035/ctzm-hz97)
C5: Identification and definition of the commons* community* and stakeholders, how their needs intersect with the commons*, and how the commons* engages with the community* to fulfill their needs | E5: - | F5: e.g. through environmental scanning (landscape reviews, etc.) to find needs, wants, aspirations of stakeholders ; competitive advantage (i,e, gaps in current Services*), community*-aligned policies and operations; e.g. Identification and communication of value chains at varying levels (e.g. biosphere > biodiversity > impact on society, data > information > knowledge > impact on a sector of application ) and usage of “success stories”, where value chains and quantitative metrics* are combined to illustrate narratives to specific stakeholders (e.g. # of citations for science funder, monetary value for agency of economic development) e.g. Different value propositions for different stakeholder groups (e.g. researchers, citizen scientists, industry and enterprises, universities, standard development organizations, policy making organizations, specialized Service* Providers*, research funding agencies, research infrastructure and e-Infrastructure) e.g.There is a statement, listing, or set of collections* that illustrates the higher-level subject areas/disciplines that the commons** covers or includes, as well as cross-disciplinary domain | G5: Core | H5: The four pillars of governance best practice for New Zealand Directors (https://www.iod.org.nz/resources-and-insights/4-pillars-landing-page/#) Twenty-Year Review of GBIF (https://doi.org/10.35035/ctzm-hz97) D5.1 FAIRsFAIR Communication, Marketing and Engagement Plan [2019. FAIRsFAIR] (https://doi.org/10.5281/zenodo.6656060) RDA Fairsharing WG
C6: Development of mission and vision statements and making them accessible publicly | E6: A vision statement is a statement of an organization’s overarching aspirations of what it hopes to achieve or to become. A mission statement describes what the organization needs to do now to achieve the vision. Mission and vision statements support each other, and neither list specific goals or actions. The mission statement however, is more actionable and leads to the creation of strategic goals. | F6: EX. The vision of the ISC is science as a global public good. The mission of the ISC is to act as the global voice of and for science. The strategic goals are that the ISC: acts as the legitimate and effective voice of science all over the world, particularly to the many components of the international policy community* ; serves as a thought leader in the evolution of science and science systems ; stimulates and support the coordination of international scientific endeavours on major issues of global concern ; promotes the appropriate and effective use of science in policy making, societal decision making and diplomacy, including by increasing trust in science and by defending freedom and responsibility in science ; acts with assurance and professionalism on behalf of a diverse, strong, global constituency of scientists. Source: (https://council.science/about-us/) | G6: Core | H6: GORC-IG Typology (https://docs.google.com/document/d/19222GItDg3tcrLsDUqg9Z7GLwPELaS-XHEbN6796Tvc/edit?usp=sharing)
C7: Development of values and/or guidance principles | E7: The values statement defines what the organization believes in and how people in the organization are expected to behave. Principles may be defined for overarching conditions (e.g ethics and integrity, inclusiveness, respect to scientific freedom etc) and for guiding the mission/objectives of the commons* (openness, excellence, quality, impact etc). | F7: EX: In fulfilling its role, the values that the Council will uphold in its work, its governance* and its partnerships include: • Excellence and professionalism ; • Inclusivity and diversity ; • Transparency and integrity ;• Innovation and sustainability (https://council.science/wp-content/uploads/2020/06/ISC-Statutes-and-Rules-of-Procedure_02.2021.pdf) e.g. openness, transparency, honesty, equity, fair competition, objectivity, democratic participation | G7: Core | H7: GORC-IG Typology (https://docs.google.com/document/d/19222GItDg3tcrLsDUqg9Z7GLwPELaS-XHEbN6796Tvc/edit?usp=sharing)
A8: Commons* Strategic Planning | E8: i.e. including governance* structure, stakeholder* strategy, sustainable operational strategy, and a strategy for the future | F8: - | G8: Core | H8: Task Group 1 Phase 1 Evaluation (October 2022 - April 2023)
C9: Development of strategy | E9: addressing how it responds to customer segments and delivers value propositions and meet its mandate etc. | F9: - | G9: Core | H9: Phase 2 Evaluation (May - September 2023)
D10: Strategic planning influences and approaches | E10: i.e. non-research or organization specific influences on how strategy is created or how strategic planning should progress. This speaks to strategic planning frameworks and methods. | F10: e.g. Consideration for shareholder vs stakeholder prioritization in strategies and planning, where a hybridization is possible e.g. Balance between performance and conformance in setting strategic goals, expectations, and metrics* (Performance here means: setting and monitoring strategy, strategic risk management, long-term attraction and allocation of human, physical, and financial matters ; Conformance means controls, reporting, compliance) | G10: Desirable | H10: The four pillars of governance best practice for New Zealand Directors (https://www.iod.org.nz/resources-and-insights/4-pillars-landing-page/#)
D11: Development of relevant roadmaps | E11: - | F11: e.g. investment roadmap, platform* roadmap, technology roadmap | G11: Core | H11: Phase 1 Workshop (co-located with RDA P20, 24 March 2023)
D12: Development of organizational performance and capability metrics* | E12: - | F12: e.g. Metrics* for 6 capitals: financial, manufactured, intellectual, human, social, relationship, natural e.g. Organizational design and capability/practise maturity, including both quantitative and qualitative KPIs*, goals, and milestones | G12: Desirable | H12: GORC-IG Typology (https://docs.google.com/document/d/19222GItDg3tcrLsDUqg9Z7GLwPELaS-XHEbN6796Tvc/edit?usp=sharing)
D13: A monitoring organizational design or organizational performance system to gather qualitative and quantitative metrics* | E13: - | F13: e.g. such as a task group or other governance* body that designs, decides on, gathers data for, and presents KPIs* | G13: Desirable | H13: Speaker Series - EOSC: https://eosc.eu/sites/default/files/2022-05/Monitoring%20Framework.pdf, from https://eosc.eu/key-performance-indicators-KPIs-monitoring
D14: Regular strategic review and alignment exercises | E14: i.e. including evaluation of KPIs*, purpose and direction of the commons*, and all governance* aspects; policy feedback cycles; identification of strategic elements; linkage to international landscape / ecosystem through needs assessments, Considerations for growth, e.g. more rigorous separation of governance* and management, changes to strategic planning, Assess environment (landscape review) including: political, economic, social, technological, environmental, legal, conduct competitor/market analysis | F14: e.g. through internal audits e.g. annual reviews as well as long-term reviews, such as decadal reviews | G14: Core | H14: Task Group 1 Phase 1 Evaluation (October 2022 - April 2023) The four pillars of governance best practice for New Zealand Directors (https://www.iod.org.nz/resources-and-insights/4-pillars-landing-page/#)
C15: Development and implementation of community* relations | E15: i.e. Engagement* with stakeholders on matters that affect them and Shareholder relations (if applicable | F15: e.g. Indigenous community* partnerships c.f. constitution, commercial relationship building | G15: Core | H15: GORC-IG Typology (https://docs.google.com/document/d/19222GItDg3tcrLsDUqg9Z7GLwPELaS-XHEbN6796Tvc/edit?usp=sharing) The four pillars of governance best practice for New Zealand Directors (https://www.iod.org.nz/resources-and-insights/4-pillars-landing-page/#)
B16: Funding and Resourcing Frameworks | E16: i.e. ensuring ability to function and continue operations | F16: - | G16: Core | H16: NIST Research Data Framework (RDaF) V1.5 (https://nvlpubs.nist.gov/nistpubs/SpecialPublications/NIST.SP.1500-18r1.pdf)
C17: Identification of the financial and resource requirements for commons* activities | E17: - | F17: - | G17: Core | H17: NIST Research Data Framework (RDaF) V1.5 (https://nvlpubs.nist.gov/nistpubs/SpecialPublications/NIST.SP.1500-18r1.pdf)
D18: Environmental considerations | E18: i.e. cost of implementing or not implementing environmentally conscious or damaging practises and infrastructure | F18: e.g. climate change and carbon footprint, environmental protection, biodiversity, pollution and resource depletion, water use, waste management, energy, sustainable procurement | G18: Desirable | H18: NIST Research Data Framework (RDaF) V1.5 (https://nvlpubs.nist.gov/nistpubs/SpecialPublications/NIST.SP.1500-18r1.pdf)
D19: Social considerations | E19: i.e. cost of implementing appropriate social obligations for Internal Personnel* and the commons* community* | F19: e.g. health and safety, labour standards*, human rights, fair trade, harassment/discrimination, people management, diversity and equality, supply chain management, privacy and ethics, consumer responsibility | G19: Desirable | H19: NIST Research Data Framework (RDaF) V1.5 (https://nvlpubs.nist.gov/nistpubs/SpecialPublications/NIST.SP.1500-18r1.pdf)
D20: Governance* considerations | E20: i.e. cost of governance* operations | F20: e.g. board composition and diversity, leadership, remuneration, shareholder rights, ethics, whistle blowing, disclosure and transparency, risk management, anti-bribery and corruption, stakeholder engagement* | G20: Desirable | H20: NIST Research Data Framework (RDaF) V1.5 (https://nvlpubs.nist.gov/nistpubs/SpecialPublications/NIST.SP.1500-18r1.pdf)
C21: Demonstration of added value | E21: Includes assessing cost (financial or otherwise) by stage or area of focus within the commons* and downstream costs. | F21: e.g. Economic impact of reuse of ROs (feeds into value statement of commons*), open source software and Tool* development and use e.g. Cost-benefit analysis for Sustainability* options | G21: Desirable | H21: NIST Research Data Framework (RDaF) V1.5 (https://nvlpubs.nist.gov/nistpubs/SpecialPublications/NIST.SP.1500-18r1.pdf)
B22: Risk Management Frameworks | E22: May have different frameworks for different types and impacts of risk, such as for governance*, management, technical and operational, related to Sustainability* etc. | F22: contingency plans to ensure Research Objects* are available and maintained during and after unforeseen events | G22: Core | H22: GORC-IG Typology (https://docs.google.com/document/d/19222GItDg3tcrLsDUqg9Z7GLwPELaS-XHEbN6796Tvc/edit?usp=sharing)
C23: Identification of risks and issues | E23: - | F23: e.g. through considerations for crises (economic (strike, market crash), financial (unexpected loss of finances), informational (cyber-attacks or leaks), physical (loss or breakdown of equipment), health (pandemics), human resources (loss of personnel), reputation, as a result of human acts (sabotage, terrorism, workplace violence), natural disasters) e.g. risk perception and literal risk | G23: Core | H23: Task Group 1 Phase 1 Evaluation (October 2022 - April 2023)
C24: Development of risk management frameworks | E24: If a full framework is untenable, a risk strategy with key considerations may suffice. The developmet of risk management frameworks considers the balance between the liklihood of the risk and the impact. | F24: - | G24: Core | H24: GORC-IG Typology (https://docs.google.com/document/d/19222GItDg3tcrLsDUqg9Z7GLwPELaS-XHEbN6796Tvc/edit?usp=sharing)
D25: Business continuity planning | E25: i.e. including how to manage identified risks, and disaster recovery plan (i.e. covering health and safety of workers, alternate premises, alternative technology platforms, key personnel strategy, plans that include customers or contractors on site, financial management including payroll systems, media management plan, infrastructure safety, essential Services*, communications, management of data and key documents) | F25: - | G25: Core | H25: The four pillars of governance best practice for New Zealand Directors (https://www.iod.org.nz/resources-and-insights/4-pillars-landing-page/#)
D26: Technology and information governance* planning | E26: i.e. considerations for cybersecurity, data protection and managing privacy breach risk, prevention of information leakage, malware risk, loss of information/data, management of capital-intensive projects, avoiding obsolescence and opportunity costs, data breach reporting, compliance with privacy and IP laws, | F26: - | G26: Core | H26: The four pillars of governance best practice for New Zealand Directors (https://www.iod.org.nz/resources-and-insights/4-pillars-landing-page/#)
D27: Health and safety governance* planning | E27: i.e. considerations for risk culture, setting policies, mental health and wellbeing | F27: - | G27: Core | H27: The four pillars of governance best practice for New Zealand Directors (https://www.iod.org.nz/resources-and-insights/4-pillars-landing-page/#)
D28: Human rights risk identification and management | E28: i.e. considering safe working conditions, fair wages, protection from forced labour, freedom from harassment and discrimination through protection, respect, remedies to breaches | F28: - | G28: Core | H28: The four pillars of governance best practice for New Zealand Directors (https://www.iod.org.nz/resources-and-insights/4-pillars-landing-page/#)
C29: Implementation and operationalization of risk management frameworks | E29: - | F29: e.g. Insurance and indemnities, including a set claims process | G29: Core | H29: Task Group 1 Phase 1 Evaluation (October 2022 - April 2023)
B30: Policy advocacy, and recommendations | E30: Advocacy towards policy makers and other stakeholders* ( i.e. Governance and leadership* role in advocacy, aligned with mission and mandate) as well as the research community* | F30: setting or informing national policy, research discipline-specific policies | G30: Desirable | H30: Phase 1 Workshop (co-located with RDA P20, 24 March 2023)
A31: Organizational structures, designs, ways of working, and capability maturity level for the aims and context of the commons* | E31: Including a clear definition of working relationships between governance* and management | F31: - | G31: Core | H31: GORC-IG Typology (https://docs.google.com/document/d/19222GItDg3tcrLsDUqg9Z7GLwPELaS-XHEbN6796Tvc/edit?usp=sharing)
C32: Explicit decision making processes, specifying who makes decisions in what scenarios and when | E32: - | F32: - | G32: Desirable | H32: GORC-WG Case Statement: https://www.rd-alliance.org/sites/default/files/GORC%20International%20Model%20WG_%20Case%20Statement%20V4%20July%202021.pdf, National Data Services IG: https://www.rd-alliance.org/groups/national-data-Services.html
D33: Formal reporting framework | E33: i.e. reporting from Management to Governance*, Governance* reporting to funders, etc. | F33: e.g. Monitoring and reporting on Key performance indicators and trend data, Monitoring of Rules of Participation & Access* and compliance, reporting on the qualitative and quantitative compliance with the rules of participation, Management reports, Operational reports | G33: Desirable | H33: Speaker Series - EOSC: https://eosc.eu/sites/default/files/2022-05/Monitoring%20Framework.pdf, from https://eosc.eu/key-performance-indicators-KPIs-monitoring, The four pillars of governance best practice for New Zealand Directors (https://www.iod.org.nz/resources-and-insights/4-pillars-landing-page/#)
C34: Systems of accountability | E34: - | F34: e.g. Governance* holds management to account through oversight of performance and conformance matters, such as operational monitoring and evaluation | G34: Desirable | H34: The four pillars of governance best practice for New Zealand Directors (https://www.iod.org.nz/resources-and-insights/4-pillars-landing-page/#)
C35: Transparency of corporate activities | E35: - | F35: - | G35: Desirable | H35: The four pillars of governance best practice for New Zealand Directors (https://www.iod.org.nz/resources-and-insights/4-pillars-landing-page/#)
B36: Governance Structures appropriate for the specific characteristics of the commons* | E36: - | F36: e.g. steering groups or boards, including external advisors where possible e.g. board committees to target key areas of work, such as an Ethics committee - provides assurance about the commons* ethical position and monitors ethical policies and behaviours of the commons* in addition to relevant developments in the commons* community*. (e.g. staff are regularly trained in ethics, breaches of ethics are reported and investigated, liaison with stakeholders is engaged over ethical matters, ethical accountability frameworks exist and are regularly maintained) | G36: Core | H36: Phase 2 Review (Literature Analysis, November 2022 - June 2023), GORC-IG Typology, Random Encounter (SMD Data and Computing Architecture Study Workshop Series, XSEDE/ACCESS), The four pillars of governance best practice for New Zealand Directors (https://www.iod.org.nz/resources-and-insights/4-pillars-landing-page/#)
C37: Creation and maintenance of governance* structure | E37: Performed by Members* of governance* and/or supporting personnel | F37: - | G37: Core | H37: The four pillars of governance best practice for New Zealand Directors (https://www.iod.org.nz/resources-and-insights/4-pillars-landing-page/#)
D38: Characteristics of governance* structure composition, particularly on boards | E38: - | F38: e.g. balance of skills and experience, diversity, stability vs new Members*hip, size, balance between executive, non-executive, and independent directors, contributions from CEO and management, and tenure on the board including procedures for exiting the board (e.g. retirement, resignation, removal, disqualification) e.g. Community* representation in the governance* structure, such as through committees, task groups, review panels, etc. | G38: Core | H38: The four pillars of governance best practice for New Zealand Directors (https://www.iod.org.nz/resources-and-insights/4-pillars-landing-page/#) Twenty-Year Review of GBIF (https://doi.org/10.35035/ctzm-hz97)
D39: Mechanisms to maintain effective relationships between governance* elements, and management, stakeholders, and shareholders | E39: i.e. appropriate support for the board depending on scale of the commons*, such as a company secretary, corporate officer, and/or secretariat, executive committee, etc. | F39: e.g. governance* reports to funders | G39: Core | H39: The four pillars of governance best practice for New Zealand Directors (https://www.iod.org.nz/resources-and-insights/4-pillars-landing-page/#)
D40: Development and regular review of constitution(s), terms of reference, and code(s) of conduct for all governance* and management structure elements and interactions | E40: i.e. May be considered for each part or level of the governance* structure together or separately, as appropriate. Includes explicit board processes, Workload plans for the board (setting calendars and agenda items, including setting a chair and chair responsibilities) legal mandate to the governance* structure | F40: e.g. federated or multi-state commons* have the appropriate documentation for each level and component of governance* e.g. If non-profit, definition of trustees, trustee duties, and terms of trust (e.g. if reliant on volunteers, fundraising, sponsorship, grants, or member subscriptions) e.g. If state-sector, considerations for reporting to ministers and hosting departments e.g. If co-operative (stakeholders are also shareholders), compliance with local laws e.g. Code of conduct is geared for minimizing conflict and promoting debate, Board supports open debate, diversity, thoughtful challenge and constructure dissent e.g. governance* frameworks/ standards* e.g. Commitment to professional development for directors e.g. Considerations for eligibility for director appointment and their remuneration | G40: Core | H40: Phase 1 Workshop (co-located with RDA P20, 24 March 2023), The four pillars of governance best practice for New Zealand Directors (https://www.iod.org.nz/resources-and-insights/4-pillars-landing-page/#)
...

Sheet Rules of Participation & Access
A1: Essential Element*: Rules of Participation & Access* | C1: Items in active view: | D1: =SUBTOTAL(103, G3:G17) -> 15 | E1: - | F1: - | G1: - | H1: -
A2: Category* | B2: Subcategory* | C2: Attribute* | D2: Feature* | E2: Extended Description | F2: Examples | G2: Consideration Level* | H2: Primary Source(s)
C3: Definition of community* of Users* and Providers* | E3: i.e. any definitions or specifications on who can participate in the research commons* as a User* or Provider* with direct access and AAI rights, with reference to the audience defined in the commons* strategic plan. Depending on the policy and use, may be an operational definition. | F3: e.g. the commons* accepts Research Object* deposits from and provides Services* to anyone regardless of affiliation; the commons* accepts Research Object* deposits from and provides Services* to the hosting institution, region, country, etc. ; the commons* accepts research deposit from and provides Services* to specific entities other than the hosting entities; etc. e.g. anyone with this account type is a part of the commons by default (e.g. EGI account holders can access CSTCloud) | G3: Core | H3: Speaker Series (NII, KISTI, ARDC); re3data Data Quality Assurance Survey (Q01), Phase 2 Evaluation (May - September 2023)
A4: A set of policies defining a minimal set of rights and obligations for the commons* community | E4: May be a singular policy document with several sections addressing different aspects of rights and obligations, or several specific policies. May also be grouped with accountability in a larger rules of participation and access* document for the commons*. | F4: - | G4: Core | H4: GORC-IG Typology (https://docs.google.com/document/d/19222GItDg3tcrLsDUqg9Z7GLwPELaS-XHEbN6796Tvc/edit?usp=sharing)
B5: Access policy | E5: A legal framework for access to Research Objects*, Services* and Tools* provided by or through the commons* (i.e. computing time, digitalisation Services*, data curation etc). and sharing of Research Objects*, in addition to a Guide or policy detailing how to share Research Objects*. | F5: - | G5: Core | H5: Phase 1 Workshop (co-located with RDA P20, 24 March 2023) ; Big Data Maturity Matrix (https://unstats.un.org/bigdata/task-teams/training/Big%20Data%20Maturity%20Matrix%20v1.0.pdf)
B6: Reuse Policy | E6: A guide or policy detailing how to reuse Research Objects*, addressing intellectual property rights, data licenses, and copyright requirements. | F6: - | G6: Core | H6: Phase 2 Review (Literature Analysis, November 2022 - June 2023), https://data.research.cornell.edu/data-management/sharing/intellectual-property/
B7: Allocation of resources policy | E7: A plan for the distribution of human and technological resources in keeping with the Commons* mission or specific KPI*s | F7: - | G7: Core | H7: Phase 1 Workshop (co-located with RDA P20, 24 March 2023), Phase 2 Review (Literature Analysis, November 2022 - June 2023)
B8: Privacy policy | E8: An openly available data and Research Object* privacy policy or policies, encompassing all Research Objects* hosted by the commons* and consistent for all users*. | F8: - | G8: Core | H8: Phase 1 Workshop (co-located with RDA P20, 24 March 2023) ; GORC-WG Case Statement: https://www.rd-alliance.org/sites/default/files/GORC%20International%20Model%20WG_%20Case%20Statement%20V4%20July%202021.pdf
B9: Retention policy | E9: i.e. for Research Objects* stored or listed within the commons* | F9: Research Objects* are assessed based on their use, impact, value, uniqueness, cost, provenance*, and legal and regulatory requirements relating to preservation, considerations for technical decisions (archiving), adminitrative or policy decisions, deaccessioning and end-of-life, legal documents, Recognition of removed data (tombstone) | G9: Core | H9: Supplemental Information to the NIH Policy for Data Management and Sharing: Selecting a Repository for Data Resulting from NIH-Supported Research (https://grants.nih.gov/grants/guide/notice-files/NOT-OD-21-016.html) NIST Research Data Framework (RDaF) V1.5 (https://nvlpubs.nist.gov/nistpubs/SpecialPublications/NIST.SP.1500-18r1.pdf)
B10: Attribution policy | E10: i.e. attribution to owners and contributors on for Research Objects*, Services* and Tools* | F10: e.g. https://creativecommons.org/choose/; https://opendatacommons.org/ | G10: Core | H10: Twenty-Year Review of GBIF (https://doi.org/10.35035/ctzm-hz97)
A11: A set of policies defining minimal accountability for the commons* community | E11: May be a singular policy document with several sections addressing different aspects of accountability, or several specific policies. May also be grouped with rights and obligations in a larger rules of participation and access* document for the commons*. | F11: - | G11: Core | H11: GORC-IG Typology (https://docs.google.com/document/d/19222GItDg3tcrLsDUqg9Z7GLwPELaS-XHEbN6796Tvc/edit?usp=sharing)
B12: Acceptable Use Policy | E12: Also referred to as "terms of use", "terms of Service*", addressing Users* and Providers* of Research Objects*, Services*, and Tools* including third party Service* Providers* and the commons* on the whole. | F12: - | G12: Core | H12: Phase 1 Workshop (co-located with RDA P20, 24 March 2023)
